<!-- AMBER 2D Model Description                                         -->
<robot name="amber3_PF">
  <material name="red">
    <color rgba="0 0 0.8 1"/>
  </material>
   <link name="world" />
 <link name="base_link" />
 <link name="base_link2" />
 <link name="base_link3" />


  <!-- Linkage Definitions -->
  <link name="torso">
    <inertial>
      <origin xyz="0 0 -0.28507"/>
      <mass value="13"/>
      <inertia ixx="0" ixy="0" ixz="0" iyy="0.5940" iyz="0" izz="0"/>
    </inertial>
    <visual>
      <geometry>
        <!--box size="0.1 0.1 0.5"/-->
        <mesh scale="0.001 0.001 0.001" filename="mesh/Torso_basic.STL"/>
      </geometry>
      <!--origin xyz="0.0 0.0 -0.25" rpy="0.0 0.0 0.0"/-->
      <origin xyz="0.08 0.2 -0.55" rpy="1.57 0 -1.57"/>
    </visual>
  </link>
  <link name="left_thigh">
    <inertial>
      <origin xyz="0.0 0.0 -0.1494" rpy= "0 0 0"/>
      <mass value="3.4261"/>
      <inertia ixx="0" ixy="0" ixz="0" iyy="0.3389" iyz="0" izz="0"/>
    </inertial>
    <visual>
      <geometry>
        <!--cylinder length="0.4046" radius="0.02"/-->
        <mesh scale="0.001 0.001 0.001" filename="mesh/Thigh_basic.STL"/>
      </geometry>
      <!--origin xyz="0.0 -0.1 -0.2" rpy="0.0 0.0 0.0"/-->
      <origin xyz="0.04 -0.02 -0.4666" rpy="1.57 0 -1.57"/>
    </visual>
  </link>
  <link name="left_shin">
    <inertial>
      <origin xyz="0 0 -0.171885" rpy="0 0 0"/>
      <mass value=".85216"/>
      <inertia ixx="0" ixy="0" ixz="0" iyy="0.219286025" iyz="0" izz="0"/>
    </inertial>
    <visual>
      <origin xyz="0.04 -0.06 -0.4666" rpy="1.57 0 -1.57"/>
      <!--origin xyz="0.0 -0.1 -0.23" rpy="0 0 0"/-->
      <geometry>
        <!--cylinder length="0.4666" radius="0.02"/-->
        <mesh scale="0.001 0.001 0.001" filename="mesh/Shank_basic.STL"/>
      </geometry>
    </visual>
    <collision>
      <origin xyz="0.0 -0.1 -0.23" rpy="0 0 0"/>
      <geometry>
        <cylinder length="0.4666" radius="0.02"/>
      </geometry>
    </collision>
  </link>
  <link name="right_thigh">
    <inertial>
      <origin xyz="0.0 0.0 -0.1494" rpy= "0 0 0"/>
      <mass value="3.4261"/>
      <inertia ixx="0" ixy="0" ixz="0" iyy="0.3389" iyz="0" izz="0"/>
    </inertial>
    <visual>
      <!--origin xyz="0.0 0.1 -0.2" rpy="0 0 0"/-->
      <origin xyz="0.04 0.18 -0.4666" rpy="1.57 0 -1.57"/>
      <geometry>
        <!--cylinder length="0.4046" radius="0.02"/-->
        <mesh scale="0.001 0.001 0.001" filename="mesh/Thigh_basic.STL"/>
      </geometry>
    </visual>
  </link>
  <link name="right_shin">
    <inertial>
      <origin xyz="0.0 0.0 -0.171885" rpy="0 0 0"/>
      <mass value="0.85216"/>
      <inertia ixx="0" ixy="0" ixz="0" iyy="0.219286025" iyz="0" izz="0"/>
    </inertial>
    <visual>
      <origin xyz="0.04 0.14 -0.4666" rpy="1.57 0 -1.57"/>
      <!--origin xyz="0.0 0.1 -0.23" rpy="0 0 0"/-->
      <geometry>
        <!--cylinder length="0.4666" radius="0.02"/-->
        <mesh scale="0.001 0.001 0.001" filename="mesh/Shank_basic.STL"/>
      </geometry>
    </visual>
    <collision>
      <origin xyz="0.0 0.1 -0.23" rpy="0 0 0"/>
      <geometry>
        <cylinder length="0.4666" radius="0.02"/>
      </geometry>
    </collision>
  </link>


  <!-- Joint Definitions -->
  <joint name="q1_left" type="revolute">
    <parent link="torso"/>
    <child link="left_thigh"/>
    <origin xyz="0 0 -0.4999" rpy="0 0 0"/>
    <axis xyz="0 1 0"/>
    <limit effort="400.0" lower="-1.6" upper="1.6" velocity="4"/>
  </joint>
  <joint name="q2_left" type="revolute">
    <parent link="left_thigh"/>
    <child link="left_shin"/>
    <origin xyz="0.0 0.0 -0.4064" rpy="0 0 0"/>
    <axis xyz="0 1 0"/>
    <limit effort="400.0" lower="0" upper="3.5" velocity="4"/>
  </joint>
    <joint name="q1_right" type="revolute">
    <parent link="torso"/>
    <child link="right_thigh"/>
    <origin xyz="0.0 0.0 -0.4999" rpy="0 0 0"/>
    <axis xyz="0 1 0"/>
    <limit effort="400.0" lower="-1.6" upper="1.6" velocity="4"/>
  </joint>
  <joint name="q2_right" type="revolute">
    <parent link="right_thigh"/>
    <child link="right_shin"/>
    <origin xyz="0.0 0.0 -0.4064" rpy="0 0 0"/>
    <axis xyz="0 1 0"/>
    <limit effort="400.0" lower="0" upper="3.5" velocity="5"/>
  </joint>

  <joint name="base_link_to_base_link2" type="revolute">
    <parent link="base_link"/>
    <child link="base_link2"/>
    <!-- <axis xyz="0 0 1"/>  -->
    <axis xyz="0 1 0"/>
    <limit effort="1000.0" lower="-1" upper="1" velocity="0.5"/>
    <origin rpy="0 0 0" xyz="0 0.0 0"/>
  </joint>

  <joint name="base_link2_to_base_link3" type="prismatic">
    <parent link="base_link2"/>
    <child link="base_link3"/>
    <!-- <axis xyz="0 1 0"/>  -->
    <axis xyz="0 0 1"/>
    <origin rpy="0 0 0" xyz="0 0.0 0"/>
  </joint>

  <joint name="base_link3_to_torso" type="prismatic">
    <parent link="base_link3"/>
    <child link="torso"/>
    <axis xyz="1 0 0"/>
    <origin rpy="0 0 0" xyz="0 0.0 0"/>
  </joint>

 <joint name="world_joint" type="fixed">
  <parent link="world"/>
   <child link="base_link"/>
  <origin rpy="0 0 0" xyz="0 0.0 0"/>
  </joint>

  <!-- Toe -->
  <link name="left_toe">
    <contact>
      <friction_anchor/>
      <stiffness value="30000000.0"/>
      <damping value="10000.0"/>
      <spinning_friction value="0.3"/>
      <lateral_friction value="3.0"/>
    </contact>
    <visual>
      <origin rpy="0 0 0" xyz="0 0 0"/>
      <geometry>
        <sphere radius="0.003"/>
      </geometry>
      <material name="darkgray"/>
    </visual>
    <collision>
      <origin rpy="0 0 0" xyz="0 0 0"/>
      <geometry>
        <sphere radius="0.003"/>
      </geometry>
    </collision>
    <inertial>
      <mass value="0.0"/>
      <inertia ixx="0.0" ixy="0" ixz="0" iyy="0.0" iyz="0" izz="0.0"/>
    </inertial>
  </link>
  <joint name="jleft_toe" type="fixed">
    <parent link="left_shin"/>
    <child link="left_toe"/>
    <origin xyz="0 -0.1 -0.4636"/>
    <dynamics damping="0.0" friction="0.0"/> 
  </joint>
<!-- Toe -->
  <link name="right_toe">
    <contact>
      <friction_anchor/>
      <stiffness value="30000000.0"/>
      <damping value="10000.0"/>
      <spinning_friction value="0.3"/>
      <lateral_friction value="3.0"/>
    </contact>
    <visual>
      <origin rpy="0 0 0" xyz="0 0 0"/>
      <geometry>
        <sphere radius="0.003"/>
      </geometry>
      <material name="darkgray"/>
    </visual>
    <collision>
      <origin rpy="0 0 0" xyz="0 0 0"/>
      <geometry>
        <sphere radius="0.003"/>
      </geometry>
    </collision>
    <inertial>
      <mass value="0.0"/>
      <inertia ixx="0.00" ixy="0" ixz="0" iyy="0.0" iyz="0" izz="0.00"/>
    </inertial>
  </link>
  <joint name="jright_toe" type="fixed">
    <parent link="right_shin"/>
    <child link="right_toe"/>
    <origin xyz="0 0.1 -0.4636"/>
    <dynamics damping="0.0" friction="0.0"/>
  </joint>
</robot>
