<?xml version="1.0" ?>
<!-- =================================================================================== -->
<!-- |    This document was autogenerated by xacro from five_link_walker.xacro         | -->
<!-- |    EDITING THIS FILE BY HAND IS NOT RECOMMENDED                                 | -->
<!-- =================================================================================== -->
<robot name="five_link_walker" xmlns:xacro="http://ros.org/wiki/xacro">
 <link name="world" />
 <link name="base_link" />
 <link name="base_link2" />
 <link name="base_link3" />
  <link name="torso">
    <inertial>
      <origin xyz="0 0 0.24" rpy="0 0 0"/>
      <mass value="13"/>
      <inertia ixx="0" ixy="0" ixz="0" iyy="0.1940" iyz="0" izz="0"/>
    </inertial>
    <visual>
      <origin xyz="0 0 0.315"/>
      <geometry>
        <cylinder length="0.63" radius="0.025"/>
      </geometry>
      <material name="black">
        <color rgba="0 0 0 1"/>
      </material>
    </visual>
  </link>
  <link name="right_thigh">
    <inertial>
      <origin xyz="0 0 0.11" rpy="0 0 0"/>
      <mass value="3.4261"/>
      <inertia ixx="0" ixy="0" ixz="0" iyy="0.0389" iyz="0" izz="0"/>
    </inertial>
    <visual>
      <origin xyz="0 0 0.2"/>
      <geometry>
        <cylinder length="0.4064" radius="0.025"/>
      </geometry>
      <material name="blue">
        <color rgba="0 0 1 1"/>
      </material>
    </visual>
  </link>
  <link name="left_thigh">
    <inertial>
      <origin xyz="0 0 0.11" rpy="0 0 0"/>
      <mass value="3.4261"/>
      <inertia ixx="0" ixy="0" ixz="0" iyy="0.0389" iyz="0" izz="0"/>
    </inertial>
    <visual>
      <origin xyz="0 0 0.2"/>
      <geometry>
        <cylinder length="0.4064" radius="0.025"/>
      </geometry>
      <material name="red">
        <color rgba="1 0 0 1"/>
      </material>
    </visual>
  </link>
  <link name="right_shin">
    <inertial>
      <origin xyz="0 0 0.24" rpy="0 0 0"/>
      <mass value="0.85216"/>
      <inertia ixx="0" ixy="0" ixz="0" iyy="0.019286025" iyz="0" izz="0"/>
    </inertial>
    <visual>
      <origin xyz="0 0 0.2"/>
      <geometry>
        <cylinder length="0.4064" radius="0.025"/>
      </geometry>
      <material name="blue">
        <color rgba="1 0 0 1"/>
      </material>
    </visual>
  </link>
  <link name="left_shin">
    <inertial>
      <origin xyz="0 0 0.24" rpy="0 0 0"/>
      <mass value="0.85216"/>
      <inertia ixx="0" ixy="0" ixz="0" iyy="0.019286025" iyz="0" izz="0"/>
    </inertial>
    <visual>
      <origin xyz="0 0 0.2"/>
      <geometry>
        <cylinder length="0.4064" radius="0.025"/>
      </geometry>
      <material name="red">
        <color rgba="0 0 1 1"/>
      </material>
    </visual>
  </link>

<!-- Toe -->
  <link name="left_toe">
    <contact>
      <friction_anchor/>
      <stiffness value="300000.0"/>
      <damping value="10000.0"/>
      <spinning_friction value="0.3"/>
      <lateral_friction value="3.0"/>
    </contact>
    <visual>
      <origin rpy="0 0 0" xyz="0 0 0"/>
      <geometry>
        <sphere radius="0.03"/>
      </geometry>
      <material name="darkgray"/>
    </visual>
    <collision>
      <origin rpy="0 0 0" xyz="0 0 0"/>
      <geometry>
        <sphere radius="0.03"/>
      </geometry>
    </collision>
    <inertial>
      <mass value="0.15"/>
      <inertia ixx="0.000025" ixy="0" ixz="0" iyy="0.000025" iyz="0" izz="0.000025"/>
    </inertial>
  </link>
  <joint name="jleft_toe" type="fixed">
    <parent link="left_shin"/>
    <child link="left_toe"/>
    <origin xyz="0 0 0.4064"/>
    <dynamics damping="0.0" friction="0.0"/>
  </joint>
<!-- Toe -->
  <link name="right_toe">
    <contact>
      <friction_anchor/>
      <stiffness value="300000.0"/>
      <damping value="10000.0"/>
      <spinning_friction value="0.3"/>
      <lateral_friction value="3.0"/>
    </contact>
    <visual>
      <origin rpy="0 0 0" xyz="0 0 0"/>
      <geometry>
        <sphere radius="0.03"/>
      </geometry>
      <material name="darkgray"/>
    </visual>
    <collision>
      <origin rpy="0 0 0" xyz="0 0 0"/>
      <geometry>
        <sphere radius="0.03"/>
      </geometry>
    </collision>
    <inertial>
      <mass value="0.15"/>
      <inertia ixx="0.000025" ixy="0" ixz="0" iyy="0.000025" iyz="0" izz="0.000025"/>
    </inertial>
  </link>
  <joint name="jright_toe" type="fixed">
    <parent link="right_shin"/>
    <child link="right_toe"/>
    <origin xyz="0 0 0.4064"/>
    <dynamics damping="0.0" friction="0.0"/>
  </joint>

  <joint name="q2_left" type="continuous">
    <origin xyz="0 0 0.4064" rpy="0 0 0"/>
    <axis xyz="0 1 0"/>
    <parent link="left_thigh"/>
    <child link="left_shin"/>
    <dynamics>
    <friction>10</friction>
    <damping>100</damping>
    <motorInertia>33200</motorInertia>
    </dynamics>
  </joint>
  <joint name="q1_right" type="continuous">
    <origin xyz="0 0.1 0" rpy="0 0 0"/>
    <axis xyz="0 1 0"/>
    <parent link="torso"/>
    <child link="right_thigh"/>
    <dynamics>
    <friction>10</friction>
    <damping>100</damping>
    </dynamics>
  </joint>
  <joint name="q1_left" type="continuous">
    <origin xyz="0 -0.1 0" rpy="0 0 0"/>
    <axis xyz="0 1 0"/>
    <parent link="torso"/>
    <child link="left_thigh"/>
    <dynamics>
    <friction>10</friction>
    <damping>100</damping>
    </dynamics>
  </joint>
   <joint name="q2_right" type="continuous">
    <origin xyz="0 0 0.4064" rpy="0 0 0"/>
    <axis xyz="0 1 0"/>
    <parent link="right_thigh"/>
    <child link="right_shin"/>
    <dynamics>
    <friction>10</friction>
    <damping>100</damping>
    </dynamics>
  </joint>

  <joint name="base_link_to_base_link2" type="revolute">
    <parent link="base_link"/>
    <child link="base_link2"/>
    <!-- <axis xyz="0 0 1"/>  -->
    <axis xyz="0 1 0"/>
    <limit effort="1000.0" lower="-1" upper="1" velocity="0.5"/>
    <origin rpy="0 0 0" xyz="0 0.0 0"/>
  </joint>

  <joint name="base_link2_to_base_link3" type="prismatic">
    <parent link="base_link2"/>
    <child link="base_link3"/>
    <!-- <axis xyz="0 1 0"/>  -->
    <axis xyz="0 0 1"/>
    <origin rpy="0 0 0" xyz="0 0.0 0"/>
  </joint>

  <joint name="base_link3_to_torso" type="prismatic">
    <parent link="base_link3"/>
    <child link="torso"/>
    <axis xyz="1 0 0"/>
    <origin rpy="0 0 0" xyz="0 0.0 0"/>
  </joint>

 <joint name="world_joint" type="fixed">
  <parent link="world"/>
   <child link="base_link"/>
  <origin rpy="0 0 0" xyz="0 0.0 0"/>
  </joint>

  
  
<transmission name="q1_right_trans" type="pr2_mechanism_model/SimpleTransmission">
  <joint name="q1_right"/>
  <actuator name="q1_right_motor"/>
  <mechanicalReduction>50</mechanicalReduction>
    <motorInertia>0.000332</motorInertia>
</transmission>

<transmission name="q2_right_trans" type="pr2_mechanism_model/SimpleTransmission">
  <joint name="q2_right"/>
  <actuator name="q2_right_motor"/>
  <mechanicalReduction>50</mechanicalReduction>
    <motorInertia>0.000332</motorInertia>
</transmission>

<transmission name="q1_left_trans" type="pr2_mechanism_model/SimpleTransmission">
  <joint name="q1_left"/>
  <actuator name="q1_left_motor"/>
  <mechanicalReduction>50</mechanicalReduction>
    <motorInertia>0.000332</motorInertia>
</transmission>

<transmission name="q2_left_trans" type="pr2_mechanism_model/SimpleTransmission">
  <joint name="q2_left"/>
  <actuator name="q2_left_motor"/>
  <mechanicalReduction>50</mechanicalReduction>
    <motorInertia>0.000332</motorInertia>
</transmission>

</robot>
